<robot xmlns:xacro="http://ros.org/wiki/xacro">
<xacro:macro name="abb_irb6700_205_280" params="prefix">
<!--  link list  -->

<material name="white">
  <color rgba="1 1 1 1"/>
</material>

<material name="grey">
  <color rgba=".7 .7 .7 1"/>
</material>

<link name="${prefix}fake_linear_axis"/>

<link name="${prefix}base_link">
  <visual>
    <origin xyz="0 0 0" rpy="0 0 0"/>
    <geometry>
      <mesh filename="package://abb_description/meshes/irb6700_205_280_itr/ManipulatorJoint0.stl" scale="0.001 0.001 0.001"/>
    </geometry>
    <material name="grey"/>
  </visual>
  <collision>
  <origin xyz="0 0 0" rpy="0 0 0"/>
  <geometry>
  <mesh filename="package://abb_description/meshes/irb6700_205_280_itr/ManipulatorJoint0.stl" scale="0.001 0.001 0.001"/>
  </geometry>
    <material name="grey"/>
  </collision>
</link>
<link name="${prefix}link_1">
  <visual>
  <origin xyz="0 0 -0.78" rpy="0 0 0"/>
  <geometry>
  <mesh filename="package://abb_description/meshes/irb6700_205_280_itr/ManipulatorJoint1.stl" scale="0.001 0.001 0.001"/>
  </geometry>
  <material name="white"/>
  </visual>
  <collision>
  <origin xyz="0 0 -0.78" rpy="0 0 0"/>
  <geometry>
  <mesh filename="package://abb_description/meshes/irb6700_205_280_itr/ManipulatorJoint1.stl" scale="0.001 0.001 0.001"/>
  </geometry>
    <material name="white"/>
  </collision>
</link>
<link name="${prefix}link_2">
  <visual>
  <origin xyz="-0.32 0 -0.78" rpy="0 0 0"/>
  <geometry>
  <mesh filename="package://abb_description/meshes/irb6700_205_280_itr/ManipulatorJoint2.stl" scale="0.001 0.001 0.001"/>
  </geometry>
    <material name="white"/>
  </visual>
  <collision>
  <origin xyz="-0.32 0 -0.78" rpy="0 0 0"/>
  <geometry>
  <mesh filename="package://abb_description/meshes/irb6700_205_280_itr/ManipulatorJoint2.stl" scale="0.001 0.001 0.001"/>
  </geometry>
    <material name="white"/>
  </collision>
</link>
<link name="${prefix}link_3">
  <visual>
  <origin xyz="-0.32 0 -2.06" rpy="0 0 0"/>
  <geometry>
  <mesh filename="package://abb_description/meshes/irb6700_205_280_itr/ManipulatorJoint3.stl" scale="0.001 0.001 0.001"/>
  </geometry>
    <material name="white"/>
  </visual>
  <collision>
  <origin xyz="-0.32 0 -2.06" rpy="0 0 0"/>
  <geometry>
  <mesh filename="package://abb_description/meshes/irb6700_205_280_itr/ManipulatorJoint3.stl" scale="0.001 0.001 0.001"/>
  </geometry>
    <material name="white"/>
  </collision>
</link>
<link name="${prefix}link_4">
  <visual>
  <origin xyz="-0.32 0 -2.26" rpy="0 0 0"/>
  <geometry>
  <mesh filename="package://abb_description/meshes/irb6700_205_280_itr/ManipulatorJoint4.stl" scale="0.001 0.001 0.001"/>
  </geometry>
    <material name="white"/>
  </visual>
  <collision>
  <origin xyz="-0.32 0 -2.26" rpy="0 0 0"/>
  <geometry>
  <mesh filename="package://abb_description/meshes/irb6700_205_280_itr/ManipulatorJoint4.stl" scale="0.001 0.001 0.001"/>
  </geometry>
    <material name="white"/>
  </collision>
</link>
<link name="${prefix}link_5">
  <visual>
  <origin xyz="-1.5025 0 -2.26" rpy="0 0 0"/>
  <geometry>
  <mesh filename="package://abb_description/meshes/irb6700_205_280_itr/ManipulatorJoint5.stl" scale="0.001 0.001 0.001"/>
  </geometry>
    <material name="white"/>
  </visual>
  <collision>
  <origin xyz="-1.5025 0 -2.26" rpy="0 0 0"/>
  <geometry>
  <mesh filename="package://abb_description/meshes/irb6700_205_280_itr/ManipulatorJoint5.stl" scale="0.001 0.001 0.001"/>
  </geometry>
    <material name="white"/>
  </collision>
</link>
<link name="${prefix}link_6">
  <visual>
  <origin xyz="-1.7025 0 -2.26" rpy="0 0 0"/>
  <geometry>
  <mesh filename="package://abb_description/meshes/irb6700_205_280_itr/ManipulatorJoint6.stl" scale="0.001 0.001 0.001"/>
  </geometry>
    <material name="white"/>
  </visual>
  <collision>
  <origin xyz="-1.7025 0 -2.26" rpy="0 0 0"/>
  <geometry>
  <mesh filename="package://abb_description/meshes/irb6700_205_280_itr/ManipulatorJoint6.stl" scale="0.001 0.001 0.001"/>
  </geometry>
    <material name="white"/>
  </collision>
</link>
<!--  joint list -->

<joint name="${prefix}joint_0" type="prismatic">
  <origin xyz="0 0 0" rpy="0 0 0"/>
  <parent link="${prefix}fake_linear_axis"/>
  <child link="${prefix}base_link"/>
  <axis xyz="0 0 1"/>
  <limit lower="0" upper="0" effort="0" velocity="1"/>
</joint>

<joint name="${prefix}joint_1" type="revolute">
  <origin xyz="0 0 0.78" rpy="0 0 0"/>
  <parent link="${prefix}base_link"/>
  <child link="${prefix}link_1"/>
  <axis xyz="0 0 1"/>
  <limit lower="-${radians(170)}" upper="${radians(170)}" effort="0" velocity="${radians(110)}"/>
</joint>
<joint name="${prefix}joint_2" type="revolute">
  <origin xyz="0.32 0 0" rpy="0 0 0"/>
  <parent link="${prefix}link_1"/>
  <child link="${prefix}link_2"/>
  <axis xyz="0 1 0"/>
  <limit lower="-${radians(65)}" upper="${radians(85)}" effort="0" velocity="${radians(110)}"/>
</joint>
<joint name="${prefix}joint_3" type="revolute">
  <origin xyz="0 0 1.280" rpy="0 0 0"/>
  <parent link="${prefix}link_2"/>
  <child link="${prefix}link_3"/>
  <axis xyz="0 1 0"/>
  <limit lower="-${radians(180)}" upper="${radians(70)}" effort="0" velocity="${radians(110)}"/>
</joint>
<joint name="${prefix}joint_4" type="revolute">
  <origin xyz="0 0 0.2" rpy="0 0 0"/>
  <parent link="${prefix}link_3"/>
  <child link="${prefix}link_4"/>
  <axis xyz="1 0 0"/>
  <limit lower="-${radians(300)}" upper="${radians(300)}" effort="0" velocity="${radians(190)}"/>
</joint>
<joint name="${prefix}joint_5" type="revolute">
  <origin xyz="1.1825 0 0" rpy="0 0 0"/>
  <parent link="${prefix}link_4"/>
  <child link="${prefix}link_5"/>
  <axis xyz="0 1 0"/>
  <limit lower="-${radians(130)}" upper="${radians(130)}" effort="0" velocity="${radians(150)}"/>
</joint>
<joint name="${prefix}joint_6" type="revolute">
  <origin xyz="0.2 0 0" rpy="0 0 0"/>
  <parent link="${prefix}link_5"/>
  <child link="${prefix}link_6"/>
  <axis xyz="1 0 0"/>
  <limit lower="-${radians(360)}" upper="${radians(360)}" effort="0" velocity="${radians(210)}"/>
</joint>
</xacro:macro>
</robot>
